Workbook
Name Anos: 'Projeto '!$D$10
Name Aporte: 'Projeto '!$D$9
Name Patrimonio: 'Projeto '!$D$12
Name Rendimento_Carteira: 'Projeto '!$D$5
Name Rendimento_Mensal: 'Projeto '!$D$11
Name Salario: 'Projeto '!$D$4
Name SegmentaçãodeDados_AÇÃO: #N/A
Name Sugestão_Investimento: 'Projeto '!$D$6

Sheet Aula 1
C7: A | D7: FEITO | E7: 1 | G7: Atividades | H7: =COUNTA(D7:D11) -> 5
C8: B | D8: EM PROGRESSO | E8: 2 | G8: Atividades Concluidas | H8: =COUNTIF(D7:D11,"FEITO") -> 3
C9: C | D9: FEITO | E9: 3
C10: D | D10: INICIAR | E10: 1
C11: E | D11: FEITO | E11: 2

Sheet Aula 2
B11: DIMENSIONAL | C11: DIMENSIONAL | D11: DIMENSIONAL | E11: FATOS | F11: CALCULADA
A12: ID OPERAÇÃO | B12: DATA OPERAÇÃO | C12: AÇÃO | D12: QUANTIDADE COMPRADA | E12: VALOR PAGO POR AÇÃO | F12: TOTAL
A13: op-01 | B13: 45708 | C13: AAPL34 | D13: 1 | E13: 10.92 | F13: =Tabela1[[#This Row],[QUANTIDADE COMPRADA]]*Tabela1[[#This Row],[VALOR PAGO POR AÇÃO]] -> 10.92
A14: op-02 | B14: 45709 | C14: NVDC34 | D14: 2 | E14: 10.97 | F14: =Tabela1[[#This Row],[QUANTIDADE COMPRADA]]*Tabela1[[#This Row],[VALOR PAGO POR AÇÃO]] -> 21.94
A15: op-03 | B15: 45710 | C15: ATVI34 | D15: 1 | E15: 10.91 | F15: =Tabela1[[#This Row],[QUANTIDADE COMPRADA]]*Tabela1[[#This Row],[VALOR PAGO POR AÇÃO]] -> 10.91
A16: op-04 | B16: 45711 | C16: AAPL34 | D16: 1 | E16: 18 | F16: =Tabela1[[#This Row],[QUANTIDADE COMPRADA]]*Tabela1[[#This Row],[VALOR PAGO POR AÇÃO]] -> 18
A17: op-05 | B17: 45712 | C17: NVDC34 | D17: 2 | E17: 13 | F17: =Tabela1[[#This Row],[QUANTIDADE COMPRADA]]*Tabela1[[#This Row],[VALOR PAGO POR AÇÃO]] -> 26
A18: op-06 | B18: 45713 | C18: AAPL34 | D18: 3 | E18: 16 | F18: =Tabela1[[#This Row],[QUANTIDADE COMPRADA]]*Tabela1[[#This Row],[VALOR PAGO POR AÇÃO]] -> 48
A19: op-07 | B19: 45714 | C19: NVDC34 | D19: 3 | E19: 17 | F19: =Tabela1[[#This Row],[QUANTIDADE COMPRADA]]*Tabela1[[#This Row],[VALOR PAGO POR AÇÃO]] -> 51
A20: op-08 | B20: 45715 | C20: NVDC34 | D20: 2 | E20: 15 | F20: =Tabela1[[#This Row],[QUANTIDADE COMPRADA]]*Tabela1[[#This Row],[VALOR PAGO POR AÇÃO]] -> 30
A21: op-09 | B21: 45716 | C21: ATVI34 | D21: 1 | E21: 18 | F21: =Tabela1[[#This Row],[QUANTIDADE COMPRADA]]*Tabela1[[#This Row],[VALOR PAGO POR AÇÃO]] -> 18
A22: op-10 | B22: 45717 | C22: NVDC34 | D22: 1 | E22: 16 | F22: =Tabela1[[#This Row],[QUANTIDADE COMPRADA]]*Tabela1[[#This Row],[VALOR PAGO POR AÇÃO]] -> 16
A23: op-11 | B23: 45718 | C23: NVDC34 | D23: 3 | E23: 11 | F23: =Tabela1[[#This Row],[QUANTIDADE COMPRADA]]*Tabela1[[#This Row],[VALOR PAGO POR AÇÃO]] -> 33
A24: op-12 | B24: 45719 | C24: NVDC34 | D24: 3 | E24: 14 | F24: =Tabela1[[#This Row],[QUANTIDADE COMPRADA]]*Tabela1[[#This Row],[VALOR PAGO POR AÇÃO]] -> 42
... A39: op-27 | B39: 45734 | C39: ATVI34 | D39: 3 | E39: 12.58 | F39: =Tabela1[[#This Row],[QUANTIDADE COMPRADA]]*Tabela1[[#This Row],[VALOR PAGO POR AÇÃO]] -> 37.74
A41: Na tabela Dinâmica, a área de LINHAS sempre é coluna Dimensional e em VALORES é a coluna de Fatos
A76: Filtros e colunas podem ter campos de dimensão como de Fato
A77: Linhas e Valores são especialistas para campo dimensão e campo fato respectivamente.
A99: Base de Normalização | B99: Mostra como era no dado original e mostra como ficou após a higienização dos nomes. Também chamado de NORMALIZE

Sheet Aula 3
A1: ID | B1: Renda_Anual | C1: Categoria_Profissional | E1: Categoria_Profissional | F1: Percentual_Imposto
A2: 1 | B2: 141958 | C2: CLT | D2: =VLOOKUP(C2,Tabela13[#All],2,FALSE) -> CLT | E2: CLT | F2: 28.56
A3: 2 | B3: 35795 | C3: AutÃ´nomo | D3: =VLOOKUP(C3,Tabela13[#All],2,FALSE) -> Autônomo | E3: Autônomo | F3: 10.99
A4: 3 | B4: 20860 | C4: CLT | D4: =VLOOKUP(C4,Tabela13[#All],2,FALSE) -> CLT | E4: CLT | F4: 20.43
A5: 4 | B5: 123694 | C5: CLT | D5: =VLOOKUP(C5,Tabela13[#All],2,FALSE) -> CLT | E5: CLT | F5: 22.77
A6: 5 | B6: 148106 | C6: CLT | D6: =VLOOKUP(C6,Tabela13[#All],2,FALSE) -> CLT | E6: CLT | F6: 6.39
A7: 6 | B7: 139879 | C7: CLT | D7: =VLOOKUP(C7,Tabela13[#All],2,FALSE) -> CLT | E7: CLT | F7: 23.23
A8: 7 | B8: 130268 | C8: AutÃ´nomo | D8: =VLOOKUP(C8,Tabela13[#All],2,FALSE) -> Autônomo | E8: Autônomo | F8: 10.12
A9: 8 | B9: 96820 | C9: AutÃ´nomo | D9: =VLOOKUP(C9,Tabela13[#All],2,FALSE) -> Autônomo | E9: Autônomo | F9: 6.95
A10: 9 | B10: 74886 | C10: CLT | D10: =VLOOKUP(C10,Tabela13[#All],2,FALSE) -> CLT | E10: CLT | F10: 33.47
A11: 10 | B11: 26265 | C11: CLT | D11: =VLOOKUP(C11,Tabela13[#All],2,FALSE) -> CLT | E11: CLT | F11: 33.97
A12: 11 | B12: 102386 | C12: AutÃ´nomo | D12: =VLOOKUP(C12,Tabela13[#All],2,FALSE) -> Autônomo | E12: Autônomo | F12: 29.25
A13: 12 | B13: 148214 | C13: AutÃ´nomo | D13: =VLOOKUP(C13,Tabela13[#All],2,FALSE) -> Autônomo | E13: Autônomo | F13: 14.14
... A21: 20 | B21: 61090 | C21: CLT | D21: =VLOOKUP(C21,Tabela13[#All],2,FALSE) -> CLT | E21: CLT | F21: 12.76
D26: Pessoas que pagam acima de | F26: 20
D27: Categoria | F27: Autônomo
A29: Planilha Base de Normalização
A30: De | B30: Para
A31: CLT | B31: CLT
A32: AutÃ´nomo | B32: Autônomo
A33: EmpresÃ¡rio | B33: Empresário

Sheet Aula 4
B3: Pessoas em cada faixa de impostos | F3: Quantidade de pessoas por faixa de impostos e tipo de fonte de renda
B5: Faixa | C5: 0.075
B7: Faixa_Imposto | C7: Quantidade | F7: Fonte_de_Renda | G7: Faixa_Imposto | H7: Quantidade | J7: Estado | K7: Faixa_Imposto | L7: Quantidade
B8: 0.075 | C8: =COUNTIF([1]Caso2!Q1:Q301,'Aula 4'!B8) -> 58 | F8: Aposentado | G8: 0.15 | H8: =COUNTIFS([1]Caso2!$M:$M,'Aula 4'!F8,[1]Caso2!$Q:$Q,'Aula 4'!G8) -> 15 | J8: AM | K8: 0.075 | L8: =COUNTIFS([1]Caso2!$L:$L,'Aula 4'!J8,[1]Caso2!$Q:$Q,'Aula 4'!K8) -> 3
B9: 0.15 | C9: =COUNTIF([1]Caso2!Q2:Q302,'Aula 4'!B9) -> 62 | F9: Aposentado | G9: 0.225 | H9: =COUNTIFS([1]Caso2!$M:$M,'Aula 4'!F9,[1]Caso2!$Q:$Q,'Aula 4'!G9) -> 17 | J9: AM | K9: 0.15 | L9: =COUNTIFS([1]Caso2!$L:$L,'Aula 4'!J9,[1]Caso2!$Q:$Q,'Aula 4'!K9) -> 6
B10: 0.225 | C10: =COUNTIF([1]Caso2!Q3:Q303,'Aula 4'!B10) -> 61 | F10: Aposentado | G10: Isento | H10: =COUNTIFS([1]Caso2!$M:$M,'Aula 4'!F10,[1]Caso2!$Q:$Q,'Aula 4'!G10) -> 10 | J10: AM | K10: 0.225 | L10: =COUNTIFS([1]Caso2!$L:$L,'Aula 4'!J10,[1]Caso2!$Q:$Q,'Aula 4'!K10) -> 6
B11: 0.275 | C11: =COUNTIF([1]Caso2!Q4:Q304,'Aula 4'!B11) -> 58 | F11: Aposentado | G11: 0.075 | H11: =COUNTIFS([1]Caso2!$M:$M,'Aula 4'!F11,[1]Caso2!$Q:$Q,'Aula 4'!G11) -> 8 | J11: AM | K11: 0.275 | L11: =COUNTIFS([1]Caso2!$L:$L,'Aula 4'!J11,[1]Caso2!$Q:$Q,'Aula 4'!K11) -> 5
B12: Isento | C12: =COUNTIF([1]Caso2!Q5:Q305,'Aula 4'!B12) -> 61 | F12: Aposentado | G12: 0.275 | H12: =COUNTIFS([1]Caso2!$M:$M,'Aula 4'!F12,[1]Caso2!$Q:$Q,'Aula 4'!G12) -> 15 | J12: AM | K12: Isento | L12: =COUNTIFS([1]Caso2!$L:$L,'Aula 4'!J12,[1]Caso2!$Q:$Q,'Aula 4'!K12) -> 5
B13: TOTAL | C13: =SUM(C8:C12) -> 300 | F13: Autônomo | G13: 0.225 | H13: =COUNTIFS([1]Caso2!$M:$M,'Aula 4'!F13,[1]Caso2!$Q:$Q,'Aula 4'!G13) -> 5 | J13: BA | K13: 0.075 | L13: =COUNTIFS([1]Caso2!$L:$L,'Aula 4'!J13,[1]Caso2!$Q:$Q,'Aula 4'!K13) -> 4
F14: Autônomo | G14: 0.275 | H14: =COUNTIFS([1]Caso2!$M:$M,'Aula 4'!F14,[1]Caso2!$Q:$Q,'Aula 4'!G14) -> 10 | J14: BA | K14: 0.15 | L14: =COUNTIFS([1]Caso2!$L:$L,'Aula 4'!J14,[1]Caso2!$Q:$Q,'Aula 4'!K14) -> 9
F15: Autônomo | G15: Isento | H15: =COUNTIFS([1]Caso2!$M:$M,'Aula 4'!F15,[1]Caso2!$Q:$Q,'Aula 4'!G15) -> 12 | J15: BA | K15: 0.225 | L15: =COUNTIFS([1]Caso2!$L:$L,'Aula 4'!J15,[1]Caso2!$Q:$Q,'Aula 4'!K15) -> 5
F16: Autônomo | G16: 0.15 | H16: =COUNTIFS([1]Caso2!$M:$M,'Aula 4'!F16,[1]Caso2!$Q:$Q,'Aula 4'!G16) -> 11 | J16: BA | K16: 0.275 | L16: =COUNTIFS([1]Caso2!$L:$L,'Aula 4'!J16,[1]Caso2!$Q:$Q,'Aula 4'!K16) -> 7
F17: Autônomo | G17: 0.075 | H17: =COUNTIFS([1]Caso2!$M:$M,'Aula 4'!F17,[1]Caso2!$Q:$Q,'Aula 4'!G17) -> 11 | J17: BA | K17: Isento | L17: =COUNTIFS([1]Caso2!$L:$L,'Aula 4'!J17,[1]Caso2!$Q:$Q,'Aula 4'!K17) -> 2
F18: Empregado CLT | G18: Isento | H18: =COUNTIFS([1]Caso2!$M:$M,'Aula 4'!F18,[1]Caso2!$Q:$Q,'Aula 4'!G18) -> 13 | J18: CE | K18: 0.075 | L18: =COUNTIFS([1]Caso2!$L:$L,'Aula 4'!J18,[1]Caso2!$Q:$Q,'Aula 4'!K18) -> 2
F19: Empregado CLT | G19: 0.275 | H19: =COUNTIFS([1]Caso2!$M:$M,'Aula 4'!F19,[1]Caso2!$Q:$Q,'Aula 4'!G19) -> 11 | J19: CE | K19: 0.15 | L19: =COUNTIFS([1]Caso2!$L:$L,'Aula 4'!J19,[1]Caso2!$Q:$Q,'Aula 4'!K19) -> 4
F20: Empregado CLT | G20: 0.225 | H20: =COUNTIFS([1]Caso2!$M:$M,'Aula 4'!F20,[1]Caso2!$Q:$Q,'Aula 4'!G20) -> 11 | J20: CE | K20: 0.225 | L20: =COUNTIFS([1]Caso2!$L:$L,'Aula 4'!J20,[1]Caso2!$Q:$Q,'Aula 4'!K20) -> 2
F21: Empregado CLT | G21: 0.075 | H21: =COUNTIFS([1]Caso2!$M:$M,'Aula 4'!F21,[1]Caso2!$Q:$Q,'Aula 4'!G21) -> 14 | J21: CE | K21: 0.275 | L21: =COUNTIFS([1]Caso2!$L:$L,'Aula 4'!J21,[1]Caso2!$Q:$Q,'Aula 4'!K21) -> 2
F22: Empregado CLT | G22: 0.15 | H22: =COUNTIFS([1]Caso2!$M:$M,'Aula 4'!F22,[1]Caso2!$Q:$Q,'Aula 4'!G22) -> 15 | J22: CE | K22: Isento | L22: =COUNTIFS([1]Caso2!$L:$L,'Aula 4'!J22,[1]Caso2!$Q:$Q,'Aula 4'!K22) -> 4
F23: Empresário | G23: 0.075 | H23: =COUNTIFS([1]Caso2!$M:$M,'Aula 4'!F23,[1]Caso2!$Q:$Q,'Aula 4'!G23) -> 15 | J23: DF | K23: 0.075 | L23: =COUNTIFS([1]Caso2!$L:$L,'Aula 4'!J23,[1]Caso2!$Q:$Q,'Aula 4'!K23) -> 5
F24: Empresário | G24: 0.225 | H24: =COUNTIFS([1]Caso2!$M:$M,'Aula 4'!F24,[1]Caso2!$Q:$Q,'Aula 4'!G24) -> 17 | J24: DF | K24: 0.15 | L24: =COUNTIFS([1]Caso2!$L:$L,'Aula 4'!J24,[1]Caso2!$Q:$Q,'Aula 4'!K24) -> 3
F25: Empresário | G25: 0.15 | H25: =COUNTIFS([1]Caso2!$M:$M,'Aula 4'!F25,[1]Caso2!$Q:$Q,'Aula 4'!G25) -> 14 | J25: DF | K25: 0.225 | L25: =COUNTIFS([1]Caso2!$L:$L,'Aula 4'!J25,[1]Caso2!$Q:$Q,'Aula 4'!K25) -> 6
F26: Empresário | G26: Isento | H26: =COUNTIFS([1]Caso2!$M:$M,'Aula 4'!F26,[1]Caso2!$Q:$Q,'Aula 4'!G26) -> 16 | J26: DF | K26: 0.275 | L26: =COUNTIFS([1]Caso2!$L:$L,'Aula 4'!J26,[1]Caso2!$Q:$Q,'Aula 4'!K26) -> 4
F27: Empresário | G27: 0.275 | H27: =COUNTIFS([1]Caso2!$M:$M,'Aula 4'!F27,[1]Caso2!$Q:$Q,'Aula 4'!G27) -> 11 | J27: DF | K27: Isento | L27: =COUNTIFS([1]Caso2!$L:$L,'Aula 4'!J27,[1]Caso2!$Q:$Q,'Aula 4'!K27) -> 2
F28: Investidor | G28: 0.275 | H28: =COUNTIFS([1]Caso2!$M:$M,'Aula 4'!F28,[1]Caso2!$Q:$Q,'Aula 4'!G28) -> 11 | J28: ES | K28: 0.075 | L28: =COUNTIFS([1]Caso2!$L:$L,'Aula 4'!J28,[1]Caso2!$Q:$Q,'Aula 4'!K28) -> 2
F29: Investidor | G29: Isento | H29: =COUNTIFS([1]Caso2!$M:$M,'Aula 4'!F29,[1]Caso2!$Q:$Q,'Aula 4'!G29) -> 10 | J29: ES | K29: 0.15 | L29: =COUNTIFS([1]Caso2!$L:$L,'Aula 4'!J29,[1]Caso2!$Q:$Q,'Aula 4'!K29) -> 7
F30: Investidor | G30: 0.075 | H30: =COUNTIFS([1]Caso2!$M:$M,'Aula 4'!F30,[1]Caso2!$Q:$Q,'Aula 4'!G30) -> 10 | J30: ES | K30: 0.225 | L30: =COUNTIFS([1]Caso2!$L:$L,'Aula 4'!J30,[1]Caso2!$Q:$Q,'Aula 4'!K30) -> 3
F31: Investidor | G31: 0.15 | H31: =COUNTIFS([1]Caso2!$M:$M,'Aula 4'!F31,[1]Caso2!$Q:$Q,'Aula 4'!G31) -> 7 | J31: ES | K31: 0.275 | L31: =COUNTIFS([1]Caso2!$L:$L,'Aula 4'!J31,[1]Caso2!$Q:$Q,'Aula 4'!K31) -> 3
F32: Investidor | G32: 0.225 | H32: =COUNTIFS([1]Caso2!$M:$M,'Aula 4'!F32,[1]Caso2!$Q:$Q,'Aula 4'!G32) -> 11 | J32: ES | K32: Isento | L32: =COUNTIFS([1]Caso2!$L:$L,'Aula 4'!J32,[1]Caso2!$Q:$Q,'Aula 4'!K32) -> 3
F33: TOTAL | H33: =SUM(H8:H32) -> 300 | J33: GO | K33: 0.075 | L33: =COUNTIFS([1]Caso2!$L:$L,'Aula 4'!J33,[1]Caso2!$Q:$Q,'Aula 4'!K33) -> 2
J34: GO | K34: 0.15 | L34: =COUNTIFS([1]Caso2!$L:$L,'Aula 4'!J34,[1]Caso2!$Q:$Q,'Aula 4'!K34) -> 1
J35: GO | K35: 0.225 | L35: =COUNTIFS([1]Caso2!$L:$L,'Aula 4'!J35,[1]Caso2!$Q:$Q,'Aula 4'!K35) -> 4
J36: GO | K36: 0.275 | L36: =COUNTIFS([1]Caso2!$L:$L,'Aula 4'!J36,[1]Caso2!$Q:$Q,'Aula 4'!K36) -> 4
J37: GO | K37: Isento | L37: =COUNTIFS([1]Caso2!$L:$L,'Aula 4'!J37,[1]Caso2!$Q:$Q,'Aula 4'!K37) -> 7
J38: MG | K38: 0.075 | L38: =COUNTIFS([1]Caso2!$L:$L,'Aula 4'!J38,[1]Caso2!$Q:$Q,'Aula 4'!K38) -> 3
J39: MG | K39: 0.15 | L39: =COUNTIFS([1]Caso2!$L:$L,'Aula 4'!J39,[1]Caso2!$Q:$Q,'Aula 4'!K39) -> 4
J40: MG | K40: 0.225 | L40: =COUNTIFS([1]Caso2!$L:$L,'Aula 4'!J40,[1]Caso2!$Q:$Q,'Aula 4'!K40) -> 1
J41: MG | K41: 0.275 | L41: =COUNTIFS([1]Caso2!$L:$L,'Aula 4'!J41,[1]Caso2!$Q:$Q,'Aula 4'!K41) -> 5
J42: MG | K42: Isento | L42: =COUNTIFS([1]Caso2!$L:$L,'Aula 4'!J42,[1]Caso2!$Q:$Q,'Aula 4'!K42) -> 5
J43: MT | K43: 0.075 | L43: =COUNTIFS([1]Caso2!$L:$L,'Aula 4'!J43,[1]Caso2!$Q:$Q,'Aula 4'!K43) -> 4
J44: MT | K44: 0.15 | L44: =COUNTIFS([1]Caso2!$L:$L,'Aula 4'!J44,[1]Caso2!$Q:$Q,'Aula 4'!K44) -> 7
...

Sheet Projeto 
B3: CONFIGURAÇÕES
B4: Salário | D4: 2000
B5: Rendimento Carteira | D5: 0.006
B6: Sugestão de Investimento (30%) | D6: =Salario*0.3 -> 600
B8: INVESTIMENTO MENSAL
B9: Quanto investir por mês ? | D9: 200
B10: Por quantos anos ? | D10: 5
B11: Taxa de Rendimento mensal ? | D11: 0.01079
B12: Patrimônio acumulado ? | D12: =FV(Rendimento_Mensal,Anos*12,-1*Aporte) -> 16755.383
B13: Dividendos Mensais ? | D13: =Patrimonio*Rendimento_Carteira -> 100.5323
B15: CENÁRIOS | D15: DIVIDENDOS
A16: 2 | B16: 2 anos | C16: =FV($D$11,A16*12,$D$9*-1) -> 5445.5255 | D16: =C16*Rendimento_Carteira -> 32.673153
A17: 5 | B17: 5 anos | C17: =FV($D$11,A17*12,$D$9*-1) -> 16755.383 | D17: =C17*Rendimento_Carteira -> 100.5323
A18: 10 | B18: 10 anos | C18: =FV($D$11,A18*12,$D$9*-1) -> 48656.843 | D18: =C18*Rendimento_Carteira -> 291.94106
A19: 20 | B19: 20 anos | C19: =FV($D$11,A19*12,$D$9*-1) -> 225039.68 | D19: =C19*Rendimento_Carteira -> 1350.2381
A20: 30 | B20: 30 anos | C20: =FV($D$11,A20*12,$D$9*-1) -> 864433.93 | D20: =C20*Rendimento_Carteira -> 5186.6036
B22: Perfil | C22: Conservador
B23: VALOR A SER INVESTIDO POR MÊS | C23: =Aporte -> 200
E24: Tabela de apoio
B25: TIPO DE FII | C25: Percentual Sugerido | D25: Valores | E25: CHAVE | F25: PERFIL | G25: TIPO DE FII | H25: %
B26: PAPEL | C26: =VLOOKUP($C$22&"-"&B26,E25:H43,4,FALSE) -> 0.3 | D26: =C26*$C$23 -> 60 | E26: =F26&"-"&G26 -> Conservador-PAPEL | F26: Conservador | G26: PAPEL | H26: 0.3
B27: TIJOLO | C27: =VLOOKUP($C$22&"-"&B27,E26:H44,4,FALSE) -> 0.5 | D27: =C27*$C$23 -> 100 | E27: =F27&"-"&G27 -> Conservador-TIJOLO | F27: Conservador | G27: TIJOLO | H27: 0.5
B28: HÍBRIDOS | C28: =VLOOKUP($C$22&"-"&B28,E27:H45,4,FALSE) -> 0.1 | D28: =C28*$C$23 -> 20 | E28: =F28&"-"&G28 -> Conservador-HÍBRIDOS | F28: Conservador | G28: HÍBRIDOS | H28: 0.1
B29: FOF's | C29: =VLOOKUP($C$22&"-"&B29,E28:H46,4,FALSE) -> 0.1 | D29: =C29*$C$23 -> 20 | E29: =F29&"-"&G29 -> Conservador-FOF's | F29: Conservador | G29: FOF's | H29: 0.1
B30: DESENVOLVIMENTO | C30: =VLOOKUP($C$22&"-"&B30,E29:H47,4,FALSE) -> 0 | D30: =C30*$C$23 -> 0 | E30: =F30&"-"&G30 -> Conservador-DESENVOLVIMENTO | F30: Conservador | G30: DESENVOLVIMENTO | H30: 0
B31: HOTELARIAS | C31: =VLOOKUP($C$22&"-"&B31,E30:H48,4,FALSE) -> 0 | D31: =C31*$C$23 -> 0 | E31: =F31&"-"&G31 -> Conservador-HOTELARIAS | F31: Conservador | G31: HOTELARIAS | H31: 0
D32: =SUM(D26:D31) -> 200 | E32: =F32&"-"&G32 -> Moderado-PAPEL | F32: Moderado | G32: PAPEL | H32: 0.32
E33: =F33&"-"&G33 -> Moderado-TIJOLO | F33: Moderado | G33: TIJOLO | H33: 0.35
E34: =F34&"-"&G34 -> Moderado-HÍBRIDOS | F34: Moderado | G34: HÍBRIDOS | H34: 0.08
E35: =F35&"-"&G35 -> Moderado-FOF's | F35: Moderado | G35: FOF's | H35: 0.05
E36: =F36&"-"&G36 -> Moderado-DESENVOLVIMENTO | F36: Moderado | G36: DESENVOLVIMENTO | H36: 0.1
E37: =F37&"-"&G37 -> Moderado-HOTELARIAS | F37: Moderado | G37: HOTELARIAS | H37: 0.1
E38: =F38&"-"&G38 -> Agressivo-PAPEL | F38: Agressivo | G38: PAPEL | H38: 0.5
E39: =F39&"-"&G39 -> Agressivo-TIJOLO | F39: Agressivo | G39: TIJOLO | H39: 0.1
E40: =F40&"-"&G40 -> Agressivo-HÍBRIDOS | F40: Agressivo | G40: HÍBRIDOS | H40: 0.05
E41: =F41&"-"&G41 -> Agressivo-FOF's | F41: Agressivo | G41: FOF's | H41: 0.05
E42: =F42&"-"&G42 -> Agressivo-DESENVOLVIMENTO | F42: Agressivo | G42: DESENVOLVIMENTO | H42: 0.2
E43: =F43&"-"&G43 -> Agressivo-HOTELARIAS | F43: Agressivo | G43: HOTELARIAS | H43: 0.1
